<?xml version="1.0" ?>
<sdf version="1.5">
  <model name="ar_ht_robot">
    <pose>0.0 0.0 0.0 0.0 0.0 0.0</pose>

    <link name="base_footprint_ideal"/>

    <link name="base_link_ideal">

      <inertial>
        <pose>-0.057 0 0.0 0.091 0 0</pose>
        <inertia>
          <ixx>0.09</ixx>
          <ixy>0.004</ixy>
          <ixz>0.009</ixz>
          <iyy>0.13</iyy>
          <iyz>-0.0008</iyz>
          <izz>0.18</izz>
        </inertia>
        <mass>15.0</mass>
      </inertial>

      <collision name="base_collision">
        <pose>0 0 0 0 0 0</pose>
        <geometry>
          <mesh>
            <uri>model://ar_ht_robot/meshes/base.dae</uri>
            <scale>0.001 0.001 0.001</scale>
          </mesh>
        </geometry>
      </collision>

      <visual name="base_visual">
        <pose>0.0 0 0 0 0 0</pose>
        <geometry>
          <mesh>
            <uri>model://ar_ht_robot/meshes/base.dae</uri>
            <scale>0.001 0.001 0.001</scale>
          </mesh>
        </geometry>
      </visual>
    </link>

    <link name="hokuyo_scan">
      <inertial>
        <pose>0.102 0 0.183 0 0 0</pose>
        <inertia>
          <ixx>0.001</ixx>
          <ixy>0.000</ixy>
          <ixz>0.000</ixz>
          <iyy>0.001</iyy>
          <iyz>0.000</iyz>
          <izz>0.001</izz>
        </inertia>
        <mass>0.01</mass>
      </inertial>

      <collision name="hokuyo_collision">
        <pose>0.102 0 0.183 0 0 0</pose>
        <geometry>
          <cylinder>
            <radius>0.0508</radius>
            <length>0.055</length>
          </cylinder>
        </geometry>
      </collision>

      <visual name="hokuyo_visual">
        <pose>0.102 0 0.183 0 0 0</pose>
        <geometry>
          <mesh>
            <uri>model://ar_ht_robot/meshes/lidar.dae</uri>
            <scale>0.001 0.001 0.001</scale>
          </mesh>
        </geometry>
      </visual>

      <sensor name="hokuyo" type="ray">
        <always_on>true</always_on>
        <visualize>true</visualize>
        <pose>0.102 0 0.216375 0 0 0</pose>
        <update_rate>5</update_rate>
        <ray>
          <scan>
            <horizontal>
              <samples>666</samples>
              <resolution>1.000000</resolution>
              <min_angle>-2.090000</min_angle>
              <max_angle>2.090000</max_angle>
            </horizontal>
          </scan>
          <range>
            <min>0.10000</min>
            <max>5.6</max>
            <resolution>0.015000</resolution>
          </range>
          <noise>
            <type>gaussian</type>
            <mean>0.0</mean>
            <stddev>0.03</stddev>
          </noise>
        </ray>
        <plugin name="hokuyo_laserscan" filename="libgazebo_ros_ray_sensor.so">
          <ros>
            <!-- <namespace>/tb3</namespace> -->
            <remapping>~/out:=scan_1</remapping>
          </ros>
          <output_type>sensor_msgs/LaserScan</output_type>
          <frame_name>scan_1</frame_name>
        </plugin>
      </sensor>
    </link>
    
    <link name="lds_scan">
      <inertial>
        <pose>-0.3335 0 0.183 0 0 -3.14</pose>
        <inertia>
          <ixx>0.001</ixx>
          <ixy>0.000</ixy>
          <ixz>0.000</ixz>
          <iyy>0.001</iyy>
          <iyz>0.000</iyz>
          <izz>0.001</izz>
        </inertia>
        <mass>0.01</mass>
      </inertial>

      <collision name="lds_collision">
        <pose>-0.3335 0 0.183 0 0 -3.14</pose>
        <geometry>
          <cylinder>
            <radius>0.0508</radius>
            <length>0.055</length>
          </cylinder>
        </geometry>
      </collision>

      <visual name="lds_visual">
        <pose>-0.3335 0 0.183 0 0 -3.14</pose>
        <geometry>
          <mesh>
            <uri>model://ar_ht_robot/meshes/lidar.dae</uri>
            <scale>0.001 0.001 0.001</scale>
          </mesh>
        </geometry>
      </visual>

      <sensor name="lds" type="ray">
        <always_on>true</always_on>
        <visualize>true</visualize>
        <pose>-0.3335 0 0.216375 0 0 0.0</pose>
        <update_rate>5</update_rate>
        <ray>
          <scan>
            <horizontal>
              <samples>220</samples>
              <resolution>1.000000</resolution>
              <min_angle>1.22000</min_angle>
              <max_angle>5.050000</max_angle>
            </horizontal>
          </scan>
          <range>
            <min>0.120000</min>
            <max>3.5</max>
            <resolution>0.015000</resolution>
          </range>
          <noise>
            <type>gaussian</type>
            <mean>0.0</mean>
            <stddev>0.03</stddev>
          </noise>
        </ray>
        <plugin name="lds_laserscan" filename="libgazebo_ros_ray_sensor.so">
          <ros>
            <!-- <namespace>/tb3</namespace> -->
            <remapping>~/out:=scan_2</remapping>
          </ros>
          <output_type>sensor_msgs/LaserScan</output_type>
          <frame_name>scan_2</frame_name>
        </plugin>
      </sensor>
    </link>

    <link name="wheel_left_link">

      <inertial>
        <pose>0.0 0.23125 0.039 1.57 0 0</pose>
        <inertia>
          <ixx>0.001</ixx>
          <ixy>0.000</ixy>
          <ixz>0.000</ixz>
          <iyy>0.001</iyy>
          <iyz>0.000</iyz>
          <izz>0.001</izz>
        </inertia>
        <mass>0.01</mass>
      </inertial>

      <collision name="wheel_left_collision">
        <pose>0.0 0.19975 0.039 1.57 0 0</pose>
        <geometry>
          <cylinder>
            <radius>0.115</radius>
            <length>0.0315</length>
          </cylinder>
        </geometry>
        <surface>
          <!-- This friction pamareter don't contain reliable data!! -->
          <friction>
            <ode>
              <mu>100000.0</mu>
              <mu2>100000.0</mu2>
              <fdir1>0 0 0</fdir1>
              <slip1>0.0</slip1>
              <slip2>0.0</slip2>
            </ode>
          </friction>
          <contact>
            <ode>
              <soft_cfm>0</soft_cfm>
              <soft_erp>0.2</soft_erp>
              <kp>1e+5</kp>
              <kd>1</kd>
              <max_vel>0.01</max_vel>
              <min_depth>0.001</min_depth>
            </ode>
          </contact>
        </surface>
      </collision>

      <visual name="wheel_left_visual">
        <pose>0.0 0.2155 0.039 1.57 0 0</pose>
        <geometry>
          <mesh>
            <uri>model://ar_ht_robot/meshes/wheel.dae</uri>
            <scale>0.001 0.001 0.001</scale>
          </mesh>
        </geometry>
      </visual>
    </link>

    <link name="wheel_right_link">

      <inertial>
        <pose>0.0 -0.19975 0.039 -1.57 0 0</pose>
        <inertia>
          <ixx>0.001</ixx>
          <ixy>0.000</ixy>
          <ixz>0.000</ixz>
          <iyy>0.001</iyy>
          <iyz>0.000</iyz>
          <izz>0.001</izz>
        </inertia>
        <mass>0.01</mass>
      </inertial>

      <collision name="wheel_right_collision">
        <pose>0.0 -0.23125 0.039 -1.57 0 0</pose>
        <geometry>
          <cylinder>
            <radius>0.115</radius>
            <length>0.0315</length>
          </cylinder>
        </geometry>
        <surface>
          <!-- This friction pamareter don't contain reliable data!! -->
          <friction>
            <ode>
              <mu>100000.0</mu>
              <mu2>100000.0</mu2>
              <fdir1>0 0 0</fdir1>
              <slip1>0.0</slip1>
              <slip2>0.0</slip2>
            </ode>
          </friction>
          <contact>
            <ode>
              <soft_cfm>0</soft_cfm>
              <soft_erp>0.2</soft_erp>
              <kp>1e+5</kp>
              <kd>1</kd>
              <max_vel>0.01</max_vel>
              <min_depth>0.001</min_depth>
            </ode>
          </contact>
        </surface>
      </collision>

      <visual name="wheel_right_visual">
        <pose>0.0 -0.2155 0.039 -1.57 0 0</pose>
        <geometry>
          <mesh>
            <uri>model://ar_ht_robot/meshes/wheel.dae</uri>
            <scale>0.001 0.001 0.001</scale>
          </mesh>
        </geometry>
      </visual>
    </link>

    <link name='caster_back_link'>
      <pose>-0.3 0 -0.038 0 0 0</pose>
      <inertial>
        <mass>1</mass>
        <inertia>
          <ixx>0.00001</ixx>
          <ixy>0.000</ixy>
          <ixz>0.000</ixz>
          <iyy>0.00001</iyy>
          <iyz>0.000</iyz>
          <izz>0.00001</izz>
        </inertia>
      </inertial>
      <collision name='collision'>
        <geometry>
          <sphere>
            <radius>0.04</radius>
          </sphere>
        </geometry>
      <surface>
          <!-- This friction pamareter don't contain reliable data!! -->
          <friction>
            <ode>
              <mu>100000.0</mu>
              <mu2>100000.0</mu2>
              <fdir1>0 0 0</fdir1>
              <slip1>0.0</slip1>
              <slip2>0.0</slip2>
            </ode>
          </friction>
          <contact>
            <ode>
              <soft_cfm>0</soft_cfm>
              <soft_erp>0.2</soft_erp>
              <kp>1e+5</kp>
              <kd>1</kd>
              <max_vel>0.01</max_vel>
              <min_depth>0.001</min_depth>
            </ode>
          </contact>
        </surface>
      </collision>
    </link>

    <joint name="base_joint" type="fixed">
      <parent>base_footprint_ideal</parent>
      <child>base_link_ideal</child>
      <pose>0.0 0.0 0.1 0 0 0</pose>
    </joint>

    <joint name="wheel_left_joint" type="revolute">
      <parent>base_link_ideal</parent>
      <child>wheel_left_link</child>
      <pose>0.0 0.2155 0.039 -1.57 0 0</pose>
      <axis>
        <xyz>0 0 1</xyz>
      </axis>
    </joint>

    <joint name="wheel_right_joint" type="revolute">
      <parent>base_link_ideal</parent>
      <child>wheel_right_link</child>
      <pose>0.0 -0.2155 0.039 -1.57 0 0</pose>
      <axis>
        <xyz>0 0 1</xyz>
      </axis>
    </joint>

    <joint name='caster_back_joint' type='ball'>
      <parent>base_link_ideal</parent>
      <child>caster_back_link</child>
    </joint>

    <joint name="hokuyo_joint" type="fixed">
      <parent>base_link_ideal</parent>
      <child>hokuyo_scan</child>
      <pose>0.102 0 0.183 0 0 0</pose>
      <axis>
        <xyz>0 0 1</xyz>
      </axis>
    </joint>
    
    <joint name="lds_joint" type="fixed">
      <parent>base_link_ideal</parent>
      <child>lds_scan</child>
      <pose>-0.102 0 0.183 0 0 0</pose>
      <axis>
        <xyz>0 0 1</xyz>
      </axis>
    </joint>

    <plugin name="ar_ht_diff_drive" filename="libgazebo_ros_diff_drive.so">

      <ros>
        <!-- <namespace>/tb3</namespace> -->
        <argument>odom:=odom_ideal</argument>
      </ros>

      <update_rate>30</update_rate>

      <!-- wheels -->
      <left_joint>wheel_left_joint</left_joint>
      <right_joint>wheel_right_joint</right_joint>

      <!-- kinematics -->
      <wheel_separation>0.414</wheel_separation>
      <wheel_diameter>0.23</wheel_diameter>

      <!-- limits -->
      <max_wheel_torque>10</max_wheel_torque>
      <max_wheel_acceleration>1.0</max_wheel_acceleration>

      <command_topic>cmd_vel</command_topic>

      <!-- output -->
      <publish_odom>true</publish_odom>
      <publish_odom_tf>false</publish_odom_tf>
      <publish_wheel_tf>false</publish_wheel_tf>

      <odometry_topic>odom_ideal</odometry_topic>
      <odometry_frame>odom_ideal</odometry_frame>
      <robot_base_frame>base_footprint_ideal</robot_base_frame>

    </plugin>

    <plugin name="ar_ht_joint_state" filename="libgazebo_ros_joint_state_publisher.so">
      <ros>
        <!-- <namespace>/tb3</namespace> -->
        <remapping>~/out:=joint_states</remapping>
      </ros>
      <update_rate>30</update_rate>
      <joint_name>wheel_left_joint</joint_name>
      <joint_name>wheel_right_joint</joint_name>
    </plugin>      
  </model>
</sdf>
